

Error occured: 2020-01-30 22:31:19
MySQL Error message: Can't connect to MySQL server on 'localhost' (111)Traceback (most recent call last):  File "/home/doms/.local/lib/python3.6/site-packages/mysql/connector/connection_cext.py", line 200, in _open_connection    self._cmysql.connect(**cnx_kwargs)_mysql_connector.MySQLInterfaceError: Can't connect to MySQL server on 'localhost' (111)During handling of the above exception, another exception occurred:Traceback (most recent call last):  File "/home/doms/Bureau/Domsdev/Projects/Library_Project/library_Python/connect_db.py", line 21, in connect_db    database = 'library'  File "/home/doms/.local/lib/python3.6/site-packages/mysql/connector/__init__.py", line 176, in connect    return CMySQLConnection(*args, **kwargs)  File "/home/doms/.local/lib/python3.6/site-packages/mysql/connector/connection_cext.py", line 80, in __init__    self.connect(**kwargs)  File "/home/doms/.local/lib/python3.6/site-packages/mysql/connector/abstracts.py", line 781, in connect    self._open_connection()  File "/home/doms/.local/lib/python3.6/site-packages/mysql/connector/connection_cext.py", line 203, in _open_connection    sqlstate=exc.sqlstate)mysql.connector.errors.DatabaseError: 2003 (HY000): Can't connect to MySQL server on 'localhost' (111)

Error occured: 2020-01-30 22:37:05
MySQL Error message: Can't connect to MySQL server on 'localhost' (111)Traceback (most recent call last):  File "/home/doms/.local/lib/python3.6/site-packages/mysql/connector/connection_cext.py", line 200, in _open_connection    self._cmysql.connect(**cnx_kwargs)_mysql_connector.MySQLInterfaceError: Can't connect to MySQL server on 'localhost' (111)During handling of the above exception, another exception occurred:Traceback (most recent call last):  File "/home/doms/Bureau/Domsdev/Projects/Library_Project/library_Python/connect_db.py", line 21, in connect_db    database = 'library'  File "/home/doms/.local/lib/python3.6/site-packages/mysql/connector/__init__.py", line 176, in connect    return CMySQLConnection(*args, **kwargs)  File "/home/doms/.local/lib/python3.6/site-packages/mysql/connector/connection_cext.py", line 80, in __init__    self.connect(**kwargs)  File "/home/doms/.local/lib/python3.6/site-packages/mysql/connector/abstracts.py", line 781, in connect    self._open_connection()  File "/home/doms/.local/lib/python3.6/site-packages/mysql/connector/connection_cext.py", line 203, in _open_connection    sqlstate=exc.sqlstate)mysql.connector.errors.DatabaseError: 2003 (HY000): Can't connect to MySQL server on 'localhost' (111)

Error occured: 2020-01-30 22:38:51
MySQL Error message: Can't connect to MySQL server on 'localhost' (111)Traceback (most recent call last):  File "/home/doms/.local/lib/python3.6/site-packages/mysql/connector/connection_cext.py", line 200, in _open_connection    self._cmysql.connect(**cnx_kwargs)_mysql_connector.MySQLInterfaceError: Can't connect to MySQL server on 'localhost' (111)During handling of the above exception, another exception occurred:Traceback (most recent call last):  File "/home/doms/Bureau/Domsdev/Projects/Library_Project/library_Python/connect_db.py", line 21, in connect_db    database = 'library'  File "/home/doms/.local/lib/python3.6/site-packages/mysql/connector/__init__.py", line 176, in connect    return CMySQLConnection(*args, **kwargs)  File "/home/doms/.local/lib/python3.6/site-packages/mysql/connector/connection_cext.py", line 80, in __init__    self.connect(**kwargs)  File "/home/doms/.local/lib/python3.6/site-packages/mysql/connector/abstracts.py", line 781, in connect    self._open_connection()  File "/home/doms/.local/lib/python3.6/site-packages/mysql/connector/connection_cext.py", line 203, in _open_connection    sqlstate=exc.sqlstate)mysql.connector.errors.DatabaseError: 2003 (HY000): Can't connect to MySQL server on 'localhost' (111)

Error occured: 2020-02-02 09:46:51
Traceback (most recent call last):  File "/home/doms/Bureau/Domsdev/Projects/Library_Project/library_Python/send_mail.py", line 87, in Send_mail    server = smtplib.SMTP_SSL("smtp.gmail.com", 465, context= context)  File "/usr/lib/python3.6/smtplib.py", line 1031, in __init__    source_address)  File "/usr/lib/python3.6/smtplib.py", line 251, in __init__    (code, msg) = self.connect(host, port)  File "/usr/lib/python3.6/smtplib.py", line 336, in connect    self.sock = self._get_socket(host, port, self.timeout)  File "/usr/lib/python3.6/smtplib.py", line 1037, in _get_socket    self.source_address)  File "/usr/lib/python3.6/socket.py", line 704, in create_connection    for res in getaddrinfo(host, port, 0, SOCK_STREAM):  File "/usr/lib/python3.6/socket.py", line 745, in getaddrinfo    for res in _socket.getaddrinfo(host, port, family, type, proto, flags):socket.gaierror: [Errno -2] Name or service not known

Error occured: 2020-02-02 19:27:55
Traceback (most recent call last):  File "/home/doms/Bureau/Domsdev/Projects/Library_Project/library_Python/send_mail.py", line 87, in Send_mail    server = smtplib.SMTP_SSL("smtp.gmail.com", 465, context= context)  File "/usr/lib/python3.6/smtplib.py", line 1031, in __init__    source_address)  File "/usr/lib/python3.6/smtplib.py", line 251, in __init__    (code, msg) = self.connect(host, port)  File "/usr/lib/python3.6/smtplib.py", line 336, in connect    self.sock = self._get_socket(host, port, self.timeout)  File "/usr/lib/python3.6/smtplib.py", line 1037, in _get_socket    self.source_address)  File "/usr/lib/python3.6/socket.py", line 704, in create_connection    for res in getaddrinfo(host, port, 0, SOCK_STREAM):  File "/usr/lib/python3.6/socket.py", line 745, in getaddrinfo    for res in _socket.getaddrinfo(host, port, family, type, proto, flags):socket.gaierror: [Errno -2] Name or service not known

Error occured: 2020-03-03 17:27:25
Traceback (most recent call last):  File "/home/doms/Bureau/Domsdev/Projects/Library_Project/library_Python/send_mail.py", line 87, in Send_mail    server = smtplib.SMTP_SSL("smtp.gmail.com", 465, context= context)  File "/usr/lib/python3.6/smtplib.py", line 1031, in __init__    source_address)  File "/usr/lib/python3.6/smtplib.py", line 251, in __init__    (code, msg) = self.connect(host, port)  File "/usr/lib/python3.6/smtplib.py", line 336, in connect    self.sock = self._get_socket(host, port, self.timeout)  File "/usr/lib/python3.6/smtplib.py", line 1037, in _get_socket    self.source_address)  File "/usr/lib/python3.6/socket.py", line 704, in create_connection    for res in getaddrinfo(host, port, 0, SOCK_STREAM):  File "/usr/lib/python3.6/socket.py", line 745, in getaddrinfo    for res in _socket.getaddrinfo(host, port, family, type, proto, flags):socket.gaierror: [Errno -2] Name or service not known

Error occured: 2020-03-03 17:27:40
Traceback (most recent call last):  File "/home/doms/Bureau/Domsdev/Projects/Library_Project/library_Python/send_mail.py", line 88, in Send_mail    server.login(sender, password)  File "/usr/lib/python3.6/smtplib.py", line 730, in login    raise last_exception  File "/usr/lib/python3.6/smtplib.py", line 721, in login    initial_response_ok=initial_response_ok)  File "/usr/lib/python3.6/smtplib.py", line 642, in auth    raise SMTPAuthenticationError(code, resp)smtplib.SMTPAuthenticationError: (534, b'5.7.14 <https://accounts.google.com/signin/continue?sarp=1&scc=1&plt=AKgnsbv\n5.7.14 mYv45eAKeGuYN4bdERUO7qJgMgbyvsT9kwy2AizjVCpqxhzIkJEGr9brxnMb_MRQOuc_J\n5.7.14 m2CJ3ksdexNmv0jAnp5JOZ5ujGkQ4Ksa2SdugiWRDLWs_fNxEwudY8TOaeBGYv1t>\n5.7.14 Please log in via your web browser and then try again.\n5.7.14  Learn more at\n5.7.14  https://support.google.com/mail/answer/78754 o18sm30339513wrv.60 - gsmtp')

Error occured: 2020-03-19 16:24:57
Traceback (most recent call last):  File "/home/doms/Bureau/Domsdev/Projects/Library_Project/library_Python/send_mail.py", line 87, in Send_mail    server = smtplib.SMTP_SSL("smtp.gmail.com", 465, context= context)  File "/usr/lib/python3.6/smtplib.py", line 1031, in __init__    source_address)  File "/usr/lib/python3.6/smtplib.py", line 251, in __init__    (code, msg) = self.connect(host, port)  File "/usr/lib/python3.6/smtplib.py", line 336, in connect    self.sock = self._get_socket(host, port, self.timeout)  File "/usr/lib/python3.6/smtplib.py", line 1037, in _get_socket    self.source_address)  File "/usr/lib/python3.6/socket.py", line 704, in create_connection    for res in getaddrinfo(host, port, 0, SOCK_STREAM):  File "/usr/lib/python3.6/socket.py", line 745, in getaddrinfo    for res in _socket.getaddrinfo(host, port, family, type, proto, flags):socket.gaierror: [Errno -2] Name or service not known

Error occured: 2020-03-19 19:10:33
Traceback (most recent call last):  File "/home/doms/Bureau/Domsdev/Projects/Library_Project/library_Python/send_mail.py", line 87, in Send_mail    server = smtplib.SMTP_SSL("smtp.gmail.com", 465, context= context)  File "/usr/lib/python3.6/smtplib.py", line 1031, in __init__    source_address)  File "/usr/lib/python3.6/smtplib.py", line 251, in __init__    (code, msg) = self.connect(host, port)  File "/usr/lib/python3.6/smtplib.py", line 336, in connect    self.sock = self._get_socket(host, port, self.timeout)  File "/usr/lib/python3.6/smtplib.py", line 1037, in _get_socket    self.source_address)  File "/usr/lib/python3.6/socket.py", line 704, in create_connection    for res in getaddrinfo(host, port, 0, SOCK_STREAM):  File "/usr/lib/python3.6/socket.py", line 745, in getaddrinfo    for res in _socket.getaddrinfo(host, port, family, type, proto, flags):socket.gaierror: [Errno -2] Name or service not known

Error occured: 2020-03-19 21:58:19
Traceback (most recent call last):  File "/home/doms/Bureau/Domsdev/Projects/Library_Project/library_Python/send_mail.py", line 87, in Send_mail    server = smtplib.SMTP_SSL("smtp.gmail.com", 465, context= context)  File "/usr/lib/python3.6/smtplib.py", line 1031, in __init__    source_address)  File "/usr/lib/python3.6/smtplib.py", line 251, in __init__    (code, msg) = self.connect(host, port)  File "/usr/lib/python3.6/smtplib.py", line 336, in connect    self.sock = self._get_socket(host, port, self.timeout)  File "/usr/lib/python3.6/smtplib.py", line 1037, in _get_socket    self.source_address)  File "/usr/lib/python3.6/socket.py", line 704, in create_connection    for res in getaddrinfo(host, port, 0, SOCK_STREAM):  File "/usr/lib/python3.6/socket.py", line 745, in getaddrinfo    for res in _socket.getaddrinfo(host, port, family, type, proto, flags):socket.gaierror: [Errno -2] Name or service not known

Error occured: 2020-03-19 21:58:23
Traceback (most recent call last):  File "/home/doms/Bureau/Domsdev/Projects/Library_Project/library_Python/send_mail.py", line 87, in Send_mail    server = smtplib.SMTP_SSL("smtp.gmail.com", 465, context= context)  File "/usr/lib/python3.6/smtplib.py", line 1031, in __init__    source_address)  File "/usr/lib/python3.6/smtplib.py", line 251, in __init__    (code, msg) = self.connect(host, port)  File "/usr/lib/python3.6/smtplib.py", line 336, in connect    self.sock = self._get_socket(host, port, self.timeout)  File "/usr/lib/python3.6/smtplib.py", line 1037, in _get_socket    self.source_address)  File "/usr/lib/python3.6/socket.py", line 704, in create_connection    for res in getaddrinfo(host, port, 0, SOCK_STREAM):  File "/usr/lib/python3.6/socket.py", line 745, in getaddrinfo    for res in _socket.getaddrinfo(host, port, family, type, proto, flags):socket.gaierror: [Errno -2] Name or service not known

Error occured: 2020-04-05 22:49:39
MySQL Error message: Access denied for user 'doms'@'localhost' (using password: NO)Traceback (most recent call last):  File "/home/doms/.local/lib/python3.6/site-packages/mysql/connector/connection_cext.py", line 216, in _open_connection    self._cmysql.connect(**cnx_kwargs)_mysql_connector.MySQLInterfaceError: Access denied for user 'doms'@'localhost' (using password: NO)During handling of the above exception, another exception occurred:Traceback (most recent call last):  File "/home/doms/Programmation/Projects/Library_Project/Library/library_python/connect_db.py", line 21, in connect_db    database = 'library'  File "/home/doms/.local/lib/python3.6/site-packages/mysql/connector/__init__.py", line 218, in connect    return CMySQLConnection(*args, **kwargs)  File "/home/doms/.local/lib/python3.6/site-packages/mysql/connector/connection_cext.py", line 80, in __init__    self.connect(**kwargs)  File "/home/doms/.local/lib/python3.6/site-packages/mysql/connector/abstracts.py", line 960, in connect    self._open_connection()  File "/home/doms/.local/lib/python3.6/site-packages/mysql/connector/connection_cext.py", line 219, in _open_connection    sqlstate=exc.sqlstate)mysql.connector.errors.ProgrammingError: 1045 (28000): Access denied for user 'doms'@'localhost' (using password: NO)