

Error occured: 2021-06-26 15:41:05
Traceback (most recent call last):  File "/home/doms/Programming/PROJECTS/Library_Managment_Interface/interface/send_mail.py", line 88, in Send_mail    server.login(sender, password)  File "/usr/lib/python3.8/smtplib.py", line 734, in login    raise last_exception  File "/usr/lib/python3.8/smtplib.py", line 723, in login    (code, resp) = self.auth(  File "/usr/lib/python3.8/smtplib.py", line 646, in auth    raise SMTPAuthenticationError(code, resp)smtplib.SMTPAuthenticationError: (535, b'5.7.8 Username and Password not accepted. Learn more at\n5.7.8  https://support.google.com/mail/?p=BadCredentials q6sm14015710wma.16 - gsmtp')